Workbook

Sheet Domaines
B1: Description | C1: Niveau 1 | D1: Niveau 2 | E1: Niveau 3 | F1: Niveau 4 | G1: Niveau 5
C2: Initiale | D2: Répétable | E2: Déini | F2: Maîtrisé | G2: Optimisé
C3: Aucune automatisation | D3: Automatisation expérimentale | E3: Automatisation de base | F3: Automatisation généralisée | G3: L’automatisation est la norme
A4: Domaines fondamentaux
A5: Catégories fondamentales et critiques permettant d’assurer un niveau de sécurité de base | H5: DevSecOps
A6: Gouvernance | B6: Gouvernance globale de l’adoption du cloud : choix des fournisseurs, politiques de sécurité, règles d’utilisation et gestion de l’architecture cloud. | C6: Aucune gouvernance liée au cloud. L’utilisation du cloud n’est pas autorisée ou n’est pas encadrée. Les équipes pourraient utiliser des services cloud de manière isolée. | D6: Certains fournisseurs cloud sont identifiés ou approuvés. Quelques politiques existent mais elles sont souvent basées sur les pratiques de sécurité de l’infrastructure interne. | E6: Une organisation commence à structurer l’adoption du cloud (équipe cloud ou référent cloud). Des politiques et standards de sécurité pour le cloud sont définis. | F6: Une équipe cloud centrale définit les règles d’utilisation et les standards de sécurité. Les responsabilités et les contrôles de sécurité cloud sont clairement définis | G6: La gouvernance cloud est intégrée dans les processus de l’organisation. Les politiques et contrôles sont maintenus et mis à jour de manière automatisée.
A7: Gestion organisationnelle | B7: Organisation et préparation de l’architecture cloud afin d’assurer des déploiements sécurisés et maîtrisés. | C7: Aucune architecture ou organisation prévue pour le cloud. Les futurs déploiements seraient réalisés sans structure claire. | D7: Premières recommandations ou checklists pour préparer les déploiements cloud. La gestion reste essentiellement manuelle. | E7: Une architecture cloud de base est définie et les contrôles de sécurité commencent à être intégrés dans la conception. | F7: Les déploiements cloud sont automatisés à l’aide d’Infrastructure as Code (IaC). Des politiques de sécurité préventives sont définies. | G7: Architecture cloud bien structurée avec automatisation complète du déploiement et de la gestion des ressources.
A8: IAM | B8: Gestion des identités, de l’authentification et des autorisations pour contrôler l’accès aux systèmes de l’organisation et préparer l’accès aux futures ressources cloud. | C8: Gestion des identités non centralisée. Peu ou pas de MFA. Pas de fédération d’identités. | D8: Premières solutions de fédération d’identités ou SSO. MFA utilisé dans certains cas mais pas généralisé. | E8: Gestion des identités plus structurée avec MFA sur plusieurs services. Politiques d’accès définies mais gestion encore partiellement manuelle. | F8: Fédération d’identités généralisée. Automatisation de la gestion des accès et gestion sécurisée des secrets. | G8: Gestion IAM entièrement automatisée. Contrôles d’accès avancés et intégration complète avec les outils et API.
A9: Supervision de la sécurité | B9: Collecte et analyse des journaux et événements de sécurité afin de détecter les incidents et surveiller les systèmes de l’organisation et les futures ressources cloud. | C9: Peu ou pas de supervision de sécurité. Les journaux sont rarement collectés ou analysés. | D9: Collecte de certains journaux de sécurité et premières alertes. La supervision reste limitée et peu centralisée. | E9: Centralisation partielle des journaux et mise en place de mécanismes de détection d’incidents. | F9: Collecte complète des journaux et détection des menaces sur les systèmes et services. Les alertes sont analysées par les équipes responsables. | G9: Supervision de sécurité avancée et centralisée avec corrélation des événements et détection automatisée des menaces.
A11: Structural Domains
A12: Protéger les composants techniques qui formeront l’infrastructure cloud
A13: Sécurité réseau | B13: Sécurisation des réseaux et des connexions entre les systèmes de l’organisation et les futures ressources cloud. | C13: Architecture réseau traditionnelle. Sécurité réseau basique et contrôles peu structurés. | D13: Premières configurations réseau adaptées au cloud. Utilisation partielle des mécanismes de sécurité cloud. | E13: Architecture réseau segmentée pour limiter les attaques. Utilisation combinée d’approches réseau cloud et hybrides. | F13: Architecture réseau cloud structurée avec segmentation et politiques de sécurité automatisées. | G13: Architecture réseau entièrement conçue pour les applications cloud avec contrôles centralisés et automatisés.
A14: Sécurité des charges de travail | B14: Protection des environnements où s’exécutent les applications et services (machines virtuelles, conteneurs ou fonctions). | C14: Applications exécutées sur des machines virtuelles avec des contrôles de sécurité hérités du datacenter. | D14: Utilisation d’outils traditionnels de gestion des infrastructures. Premières automatisations de configuration. | E14: Utilisation d’outils cloud natifs et premières intégrations de sécurité dans les processus de déploiement. | F14: Infrastructure immuable utilisée lorsque possible. La sécurité est intégrée dans les pipelines de déploiement. | G14: Infrastructure immuable et déploiements fréquents automatisés. Les mécanismes de sécurité sont intégrés en continu dans les services et fonctions cloud.
A15: Sécurité applicative | B15: Sécurité des applications sur l’ensemble de l’architecture (tests de sécurité, protection des pipelines de déploiement et des services). | C15: Tests de sécurité traditionnels des applications (AST) et protections classiques comme les WAF. | D15: Tests principalement manuels et évaluations ponctuelles de la sécurité des pipelines. Première utilisation d’outils de sécurité des applications. | E15: Tests de sécurité spécifiques au cloud. Protection des applications exposées (WAF/DDoS) et intégration des tests de sécurité dans les pipelines CI/CD. | F15: Tests de sécurité automatisés dans les pipelines CI/CD. Utilisation de mécanismes de sécurité applicative (AppSec guardrails). | G15: Tests de sécurité entièrement automatisés pour toutes les applications. Utilisation d’équipes ou processus de type red team pour tester les applications cloud.
A16: Protection des données | B16: Protection des données par des mécanismes de contrôle d’accès, de chiffrement et de gestion des clés. | C16: Contrôles d’accès basiques et souvent mal configurés. | D16: Chiffrement activé avec des configurations simples et gestion manuelle des clés. | E16: Première utilisation de clés gérées par l’organisation et automatisation partielle des contrôles d’accès. | F16: Utilisation généralisée de clés gérées par l’organisation. Chiffrement des données critiques et contrôles d’accès basés sur des politiques. | G16: Gestion avancée des clés et chiffrement automatisé. Surveillance continue des données et détection des données non autorisées.
A18: Domaines Procéduraux
A19: Catégories qui décrivent les processus organisationnels nécessaires pour sécuriser l’utilisation du cloud et maintenir ce niveau de sécurité dans le temps.
A20: Évaluation des risques et gestion des fournisseurs | B20: L’évaluation des risques comprend trois aspects :: 1)la sélection des fournisseurs cloud, 2) le suivi et la réévaluation continue des fournisseurs, and 3) l’analyse des risques liés aux projets et aux migrations vers le cloud.. | C20: Utilisation des méthodes existantes d’analyse de risques sans processus spécifique pour le cloud. | D20: Le choix des fournisseurs est principalement réalisé par les équipes métiers. La sécurité peut intervenir pour évaluer les risques mais de manière irrégulière. | E20: Des standards de sécurité de base sont définis pour les différents modèles cloud (IaaS, PaaS, SaaS). Un registre des fournisseurs cloud est établi avec un premier niveau d’évaluation des risques. | F20: La sécurité participe systématiquement à l’évaluation des fournisseurs et des déploiements cloud. Les risques sont réévalués régulièrement et les approbations sont formalisées. | G20: Les évaluations de risques sont intégrées dans les projets cloud et les migrations. Les fournisseurs et les projets sont analysés en continu et les profils de risque sont régulièrement mis à jour.
A21: Résilience | B21: Capacité de l’organisation à assurer la disponibilité, la continuité d’activité et la reprise après incident pour les systèmes et les futures ressources cloud. | C21: Aucun mécanisme spécifique de résilience pour les environnements cloud. | D21: Mise en place de sauvegardes et premiers mécanismes de reprise. Les déploiements restent généralement dans une seule région ou infrastructure. | E21: Utilisation partielle de mécanismes d’automatisation et de scalabilité pour améliorer la résilience. Début d’utilisation de déploiements multi-zones ou multi-régions. | F21: La majorité des déploiements sont automatisés avec Infrastructure as Code (IaC). Certaines architectures multi-régions sont utilisées pour améliorer la continuité de service. | G21: Tous les déploiements critiques utilisent l’Infrastructure as Code. Les mécanismes de basculement automatique, de reprise et de résilience sont intégrés dans l’architecture.
A22: Conformité et Audit | B22: Respect des exigences réglementaires, des normes et des obligations de conformité applicables à l’utilisation du cloud. | C22: Aucun reporting ni action de conformité spécifique pour les ressources cloud. | D22: Absence de standards spécifiques au cloud. Les évaluations de conformité et les corrections sont réalisées de manière ponctuelle. | E22: Les fournisseurs cloud et leurs services sont approuvés. Des évaluations régulières sont réalisées et les contrôles sont comparés aux standards de conformité. | F22: Évaluation continue des ressources grâce à des mécanismes automatisés. Les corrections restent en partie manuelles et le reporting est partiellement automatisé. | G22: Évaluation continue et correction automatique des écarts de conformité grâce à l’automatisation cloud. Le reporting est entièrement automatisé avec des tableaux de bord.
A23: Réponse aux incidents | B23: Processus permettant de détecter, analyser et répondre aux incidents de sécurité liés aux systèmes et aux futures ressources cloud. | C23: Aucun processus spécifique de réponse aux incidents liés au cloud. Les procédures existantes sont utilisées si elles existent. | D23: Réponse manuelle aux incidents. La collecte d’informations et l’escalade des incidents sont encore incohérentes. | E23: Réponse aux incidents structurée mais encore principalement manuelle. Utilisation d’outils basiques de gestion des incidents. | F23: Les équipes utilisent des outils et des processus adaptés au cloud. Certaines actions de réponse sont automatisées. | G23: Processus de réponse aux incidents entièrement automatisé et orchestré. Des simulations et tests réguliers (type red team ou exercices de crise) sont réalisés.

Sheet Echelles
B3: Niveau de maturité
B4: Initiale | C4: La sécurité est gérée manuellement et de manière non structurée. Peu d’utilisation des fonctionnalités avancées du cloud et IAM peu organisé.
B5: Répétable | C5: Des politiques de sécurité existent, mais elles sont appliquées manuellement et de façon incohérente selon les équipes. L’automatisation et le MFA sont encore limités.
B6: Défini | C6: Les politiques de sécurité sont centralisées et standardisées. Certaines automatisations apparaissent et des outils de sécurité cloud commencent à être utilisés.
B7: Maîtrisé | C7: La sécurité est centralisée et largement automatisée. Elle est intégrée dans l’Infrastructure as Code et les pipelines de déploiement.
B8: Optimisé | C8: La sécurité est entièrement intégrée, automatisée et pilotée par des plateformes centralisées. Les contrôles sont cohérents et appliqués à grande échelle.
B9: Non applicable | C9: Le contrôle ne s’applique pas au contexte, à l’architecture ou aux technologies utilisées par l’organisation. Il est donc exclu de l’évaluation de maturité pour cet environnement.

Sheet Feuil1
A1: 1 | B1: Initiale | C1: La sécurité est gérée manuellement et de manière non structurée. Peu d’utilisation des fonctionnalités avancées du cloud et IAM peu organisé.
A2: 2 | B2: Répétable | C2: Des politiques de sécurité existent, mais elles sont appliquées manuellement et de façon incohérente selon les équipes. L’automatisation et le MFA sont encore limités.
A3: 3 | B3: Défini | C3: Les politiques de sécurité sont centralisées et standardisées. Certaines automatisations apparaissent et des outils de sécurité cloud commencent à être utilisés.
A4: 4 | B4: Maîtrisé | C4: La sécurité est centralisée et largement automatisée. Elle est intégrée dans l’Infrastructure as Code et les pipelines de déploiement.
A5: 5 | B5: Optimisé | C5: La sécurité est entièrement intégrée, automatisée et pilotée par des plateformes centralisées. Les contrôles sont cohérents et appliqués à grande échelle.
A6: NA | B6: Non applicable | C6: Le contrôle ne s’applique pas au contexte, à l’architecture ou aux technologies utilisées par l’organisation. Il est donc exclu de l’évaluation de maturité pour cet environnement.

Sheet Gouvernance
A1: ID | B1: Nom du contrôle | C1: Description du contrôle | D1: Niveau de maturité | E1: Libellé | F1: Signification | G1: Commentaires
A2: GOV-02.1 | B2: Fournisseurs cloud approuvés | C2: L’organisation a identifié et validé les fournisseurs cloud autorisés à être utilisés. | D2: 4 | E2: =IFERROR(VLOOKUP(D2,Feuil1!A:B,2,FALSE),"") -> Maîtrisé | F2: =IFERROR(VLOOKUP(D2,Feuil1!A:C,3,FALSE),"") -> La sécurité est centralisée et largement automatisée. Elle est intégrée dans l’Infrastructure as Code et les pipelines de déploiement.
A3: GOV-03.1 | B3: Existence d’un Cloud Center of Excellence (CCoE) | C3: Un Cloud Center of Excellence (CCoE), un Cloud Council ou une équipe centrale de gouvernance cloud est en place pour guider l’adoption et l’utilisation du cloud. Pour un niveau de maturité 3, cette équipe peut encore être en phase de structuration. Dans les organisations plus petites, ce rôle peut être assuré par l’équipe IT ou sécurité existante, sans qu’un CCoE formel soit nécessaire. | D3: 1 | E3: =IFERROR(VLOOKUP(D3,Feuil1!A:B,2,FALSE),"") -> Initiale | F3: =IFERROR(VLOOKUP(D3,Feuil1!A:C,3,FALSE),"") -> La sécurité est gérée manuellement et de manière non structurée. Peu d’utilisation des fonctionnalités avancées du cloud et IAM peu organisé.
A4: GOV-03.2 | B4: Premiers référentiels de sécurité définis | C4: L’organisation a défini des standards de sécurité pour encadrer l’utilisation future du cloud (ex : CIS Benchmarks ou bonnes pratiques des fournisseurs cloud). | D4: 5 | E4: =IFERROR(VLOOKUP(D4,Feuil1!A:B,2,FALSE),"") -> Optimisé | F4: =IFERROR(VLOOKUP(D4,Feuil1!A:C,3,FALSE),"") -> La sécurité est entièrement intégrée, automatisée et pilotée par des plateformes centralisées. Les contrôles sont cohérents et appliqués à grande échelle.
A5: GOV-03.3 | B5: Existence d’un registre des ressources cloud | C5: Un registre centralisé des fournisseurs cloud et des déploiements est maintenu (responsable, type d’environnement, niveau de risque, etc.). | D5: 5 | E5: =IFERROR(VLOOKUP(D5,Feuil1!A:B,2,FALSE),"") -> Optimisé | F5: =IFERROR(VLOOKUP(D5,Feuil1!A:C,3,FALSE),"") -> La sécurité est entièrement intégrée, automatisée et pilotée par des plateformes centralisées. Les contrôles sont cohérents et appliqués à grande échelle.
A6: GOV-04.1 | B6: CCoE dispose d’une autorité | C6: Une équipe ou autorité centrale définit et applique les règles de sécurité cloud. | D6: 3 | E6: =IFERROR(VLOOKUP(D6,Feuil1!A:B,2,FALSE),"") -> Défini | F6: =IFERROR(VLOOKUP(D6,Feuil1!A:C,3,FALSE),"") -> Les politiques de sécurité sont centralisées et standardisées. Certaines automatisations apparaissent et des outils de sécurité cloud commencent à être utilisés.
A7: GOV-04.2 | B7: Objectifs de sécurité cloud définis | C7: L’organisation définit des objectifs de sécurité pour l’utilisation du cloud, basés sur des référentiels reconnus (ex. CSA CCM). | D7: 2 | E7: =IFERROR(VLOOKUP(D7,Feuil1!A:B,2,FALSE),"") -> Répétable | F7: =IFERROR(VLOOKUP(D7,Feuil1!A:C,3,FALSE),"") -> Des politiques de sécurité existent, mais elles sont appliquées manuellement et de façon incohérente selon les équipes. L’automatisation et le MFA sont encore limités.
A8: GOV-04.3 | B8: Spécifications de contrôle appliquées | C8: Des contrôles de sécurité techniques sont définis et appliqués pour les fournisseurs cloud utilisés. | D8: 4 | E8: =IFERROR(VLOOKUP(D8,Feuil1!A:B,2,FALSE),"") -> Maîtrisé | F8: =IFERROR(VLOOKUP(D8,Feuil1!A:C,3,FALSE),"") -> La sécurité est centralisée et largement automatisée. Elle est intégrée dans l’Infrastructure as Code et les pipelines de déploiement.
A9: GOV-04.4 | B9: Gouvernance cloud automatisée | C9: La gouvernance et les contrôles de sécurité cloud sont gérés à l’aide d’outils d’automatisation (ex. IaC, CI/CD). | D9: 4 | E9: =IFERROR(VLOOKUP(D9,Feuil1!A:B,2,FALSE),"") -> Maîtrisé | F9: =IFERROR(VLOOKUP(D9,Feuil1!A:C,3,FALSE),"") -> La sécurité est centralisée et largement automatisée. Elle est intégrée dans l’Infrastructure as Code et les pipelines de déploiement.
A10: GOV-05.1 | B10: Mise à jour continue des objectifs et contrôles de sécurité cloud | C10: Les objectifs et contrôles de sécurité cloud sont mis à jour régulièrement en fonction de l’évolution des services des fournisseurs cloud. | D10: 4 | E10: =IFERROR(VLOOKUP(D10,Feuil1!A:B,2,FALSE),"") -> Maîtrisé | F10: =IFERROR(VLOOKUP(D10,Feuil1!A:C,3,FALSE),"") -> La sécurité est centralisée et largement automatisée. Elle est intégrée dans l’Infrastructure as Code et les pipelines de déploiement.

Sheet Gestion organisationnelle
A1: ID | B1: Nom du contrôle | C1: Description du contrôle | D1: Niveau de maturité | E1: Libellé | F1: Signification | G1: Commentaires
A2: ORM-02.1 | B2: Déploiements organisés dans une hiérarchie | C2: Les déploiements cloud sont structurés dans une hiérarchie. | D2: 4 | E2: =IFERROR(VLOOKUP(D2,Feuil1!A:B,2,FALSE),"") -> Maîtrisé | F2: =IFERROR(VLOOKUP(D2,Feuil1!A:C,3,FALSE),"") -> La sécurité est centralisée et largement automatisée. Elle est intégrée dans l’Infrastructure as Code et les pipelines de déploiement.
A3: ORM-02.2 | B3: Checklist de sécurité | C3: Une checklist de contrôles de sécurité est utilisée pour vérifier les nouveaux déploiements et peut être documentée ou automatisée via des outils de sécurité. | D3: 4 | E3: =IFERROR(VLOOKUP(D3,Feuil1!A:B,2,FALSE),"") -> Maîtrisé | F3: =IFERROR(VLOOKUP(D3,Feuil1!A:C,3,FALSE),"") -> La sécurité est centralisée et largement automatisée. Elle est intégrée dans l’Infrastructure as Code et les pipelines de déploiement.
A4: ORM-03.1 | B4: CSPM implémenté et utilisé | C4: Un outil de gestion de la posture de sécurité cloud (CSPM) est utilisé pour détecter les mauvaises configurations dans les déploiements cloud. | D4: 3 | E4: =IFERROR(VLOOKUP(D4,Feuil1!A:B,2,FALSE),"") -> Défini | F4: =IFERROR(VLOOKUP(D4,Feuil1!A:C,3,FALSE),"") -> Les politiques de sécurité sont centralisées et standardisées. Certaines automatisations apparaissent et des outils de sécurité cloud commencent à être utilisés.
A5: ORM-03.2 | B5: Politiques préventives du fournisseur cloud utilisées | C5: Des politiques de sécurité préventives du fournisseur cloud sont appliquées dans l’organisation. | D5: 5 | E5: =IFERROR(VLOOKUP(D5,Feuil1!A:B,2,FALSE),"") -> Optimisé | F5: =IFERROR(VLOOKUP(D5,Feuil1!A:C,3,FALSE),"") -> La sécurité est entièrement intégrée, automatisée et pilotée par des plateformes centralisées. Les contrôles sont cohérents et appliqués à grande échelle.
A6: ORM-04.1 | B6: Déploiements utilisés pour limiter l’impact des incidents | C6: Les déploiements sont organisés dans une structure hiérarchique (comptes, abonnements, projets, etc.) afin de limiter l’impact d’un incident de sécurité sur l’ensemble de l’environnement. | D6: 2 | E6: =IFERROR(VLOOKUP(D6,Feuil1!A:B,2,FALSE),"") -> Répétable | F6: =IFERROR(VLOOKUP(D6,Feuil1!A:C,3,FALSE),"") -> Des politiques de sécurité existent, mais elles sont appliquées manuellement et de façon incohérente selon les équipes. L’automatisation et le MFA sont encore limités.
A7: ORM-04.2 | B7: Les politiques préventives du fournisseur cloud sont utilisées de manière cohérente | C7: Les politiques de sécurité préventives du fournisseur cloud (par exemple AWS Service Control Policies, Azure Policies ou GCP Policies) sont utilisées et appliquées dans l’ensemble de l’organisation afin de contrôler les déploiements. | D7: 1 | E7: =IFERROR(VLOOKUP(D7,Feuil1!A:B,2,FALSE),"") -> Initiale | F7: =IFERROR(VLOOKUP(D7,Feuil1!A:C,3,FALSE),"") -> La sécurité est gérée manuellement et de manière non structurée. Peu d’utilisation des fonctionnalités avancées du cloud et IAM peu organisé.
A8: ORM-05.1 | B8: Les contrôles de sécurité sont automatiquement déployés et gérés par automatisation | C8: Les déploiements cloud sont automatisés et incluent automatiquement les principaux contrôles de sécurité. | D8: 4 | E8: =IFERROR(VLOOKUP(D8,Feuil1!A:B,2,FALSE),"") -> Maîtrisé | F8: =IFERROR(VLOOKUP(D8,Feuil1!A:C,3,FALSE),"") -> La sécurité est centralisée et largement automatisée. Elle est intégrée dans l’Infrastructure as Code et les pipelines de déploiement.

Sheet IAM
A1: ID | B1: Nom du contrôle | C1: Description du contrôle | D1: Niveau de maturité | E1: Libellé | F1: Signification | G1: Commentaires
A2: IAM-02.1 | B2: SSO utilisé pour la majorité des accès à la console cloud | C2: L’accès à la console ou au portail du fournisseur cloud se fait via un système d’authentification unique (SSO), fourni par un service externe ou intégré à la plateforme cloud. | D2: 2 | E2: =IFERROR(VLOOKUP(D2,Feuil1!A:B,2,FALSE),"") -> Répétable | F2: =IFERROR(VLOOKUP(D2,Feuil1!A:C,3,FALSE),"") -> Des politiques de sécurité existent, mais elles sont appliquées manuellement et de façon incohérente selon les équipes. L’automatisation et le MFA sont encore limités.
A3: IAM-02.2 | B3: MFA requis pour l’accès à la console cloud | C3: L’accès à la console cloud nécessite une authentification multifacteur (MFA). | D3: 4 | E3: =IFERROR(VLOOKUP(D3,Feuil1!A:B,2,FALSE),"") -> Maîtrisé | F3: =IFERROR(VLOOKUP(D3,Feuil1!A:C,3,FALSE),"") -> La sécurité est centralisée et largement automatisée. Elle est intégrée dans l’Infrastructure as Code et les pipelines de déploiement.
A4: IAM-03.1 | B4: Les utilisateurs accèdent à la console cloud uniquement via le SSO | C4: L’accès à la console cloud est uniquement possible via le portail SSO. Un compte d’urgence peut exister pour les situations exceptionnelles. | D4: 3 | E4: =IFERROR(VLOOKUP(D4,Feuil1!A:B,2,FALSE),"") -> Défini | F4: =IFERROR(VLOOKUP(D4,Feuil1!A:C,3,FALSE),"") -> Les politiques de sécurité sont centralisées et standardisées. Certaines automatisations apparaissent et des outils de sécurité cloud commencent à être utilisés.
A5: IAM-03.2 | B5: MFA appliqué pour les accès API et CLI | C5: L’authentification multifacteur est également appliquée aux accès via API ou ligne de commande (CLI) afin de sécuriser les accès programmatiques au cloud. | D5: 1 | E5: =IFERROR(VLOOKUP(D5,Feuil1!A:B,2,FALSE),"") -> Initiale | F5: =IFERROR(VLOOKUP(D5,Feuil1!A:C,3,FALSE),"") -> La sécurité est gérée manuellement et de manière non structurée. Peu d’utilisation des fonctionnalités avancées du cloud et IAM peu organisé.
A6: IAM-04.1 | B6: Les politiques IAM sont automatiquement analysées pour détecter les accès trop larges ou les risques d’escalade de privilèges | C6: Les politiques IAM sont analysées pour détecter les privilèges excessifs et les risques d’escalade. | D6: 3 | E6: =IFERROR(VLOOKUP(D6,Feuil1!A:B,2,FALSE),"") -> Défini | F6: =IFERROR(VLOOKUP(D6,Feuil1!A:C,3,FALSE),"") -> Les politiques de sécurité sont centralisées et standardisées. Certaines automatisations apparaissent et des outils de sécurité cloud commencent à être utilisés.
A7: IAM-05.1 | B7: Un périmètre de sécurité IAM est appliqué | C7: Un périmètre de sécurité IAM limite l’origine des appels API et l’accès aux ressources cloud, par exemple en utilisant : - des restrictions d’adresses IP - des contraintes sur les appareils ou les environnements autorisés. L’objectif est d’empêcher l’utilisation abusive de credentials ou de sessions volées. | D7: 5 | E7: =IFERROR(VLOOKUP(D7,Feuil1!A:B,2,FALSE),"") -> Optimisé | F7: =IFERROR(VLOOKUP(D7,Feuil1!A:C,3,FALSE),"") -> La sécurité est entièrement intégrée, automatisée et pilotée par des plateformes centralisées. Les contrôles sont cohérents et appliqués à grande échelle.
A8: IAM-05.2 | B8: Accès Just-In-Time (JIT) utilisé pour les environnements de production | C8: L’accès aux environnements de production est accordé temporairement à la demande, plutôt que de permettre des accès permanents aux utilisateurs. | D8: 4 | E8: =IFERROR(VLOOKUP(D8,Feuil1!A:B,2,FALSE),"") -> Maîtrisé | F8: =IFERROR(VLOOKUP(D8,Feuil1!A:C,3,FALSE),"") -> La sécurité est centralisée et largement automatisée. Elle est intégrée dans l’Infrastructure as Code et les pipelines de déploiement.

Sheet Supervision de la sécurité
A1: ID | B1: Nom du contrôle | C1: Description du contrôle | D1: Niveau de maturité | E1: Libellé | F1: Signification | G1: Commentaires
A2: LOG-02.1 | B2: Collecte de logs de base mise en place mais pas encore cohérente | C2: Les principaux logs du plan de gestion du cloud sont collectés, mais la collecte peut ne pas être centralisée ou uniforme. Les logs d’activité cloud sont au minimum collectés pour la majorité des déploiements. | D2: 5 | E2: =IFERROR(VLOOKUP(D2,Feuil1!A:B,2,FALSE),"") -> Optimisé | F2: =IFERROR(VLOOKUP(D2,Feuil1!A:C,3,FALSE),"") -> La sécurité est entièrement intégrée, automatisée et pilotée par des plateformes centralisées. Les contrôles sont cohérents et appliqués à grande échelle.
A3: LOG-03.1 | B3: Les logs d’activité API du plan de gestion sont collectés et centralisés | C3: Les logs liés aux activités du plan de gestion du cloud sont collectés de manière cohérente et centralisés. | D3: 1 | E3: =IFERROR(VLOOKUP(D3,Feuil1!A:B,2,FALSE),"") -> Initiale | F3: =IFERROR(VLOOKUP(D3,Feuil1!A:C,3,FALSE),"") -> La sécurité est gérée manuellement et de manière non structurée. Peu d’utilisation des fonctionnalités avancées du cloud et IAM peu organisé.
A4: LOG-03.2 | B4: Les flux de détection des menaces du fournisseur cloud sont activés | C4: Les flux de sécurité et de détection des menaces fournis par les fournisseurs cloud sont activés et collectés au moins pour les environnements de production, afin d’identifier les activités suspectes. | D4: 2 | E4: =IFERROR(VLOOKUP(D4,Feuil1!A:B,2,FALSE),"") -> Répétable | F4: =IFERROR(VLOOKUP(D4,Feuil1!A:C,3,FALSE),"") -> Des politiques de sécurité existent, mais elles sont appliquées manuellement et de façon incohérente selon les équipes. L’automatisation et le MFA sont encore limités.
A5: LOG-04.1 | B5: Télémétrie de sécurité cloud collectée de manière centralisée | C5: Les différentes sources de télémétrie de sécurité du cloud (logs, événements de sécurité, flux de détection, logs des workloads) sont collectées et centralisées afin d’améliorer la supervision et la détection des incidents. | D5: 5 | E5: =IFERROR(VLOOKUP(D5,Feuil1!A:B,2,FALSE),"") -> Optimisé | F5: =IFERROR(VLOOKUP(D5,Feuil1!A:C,3,FALSE),"") -> La sécurité est entièrement intégrée, automatisée et pilotée par des plateformes centralisées. Les contrôles sont cohérents et appliqués à grande échelle.
A6: LOG-04.2 | B6: Les détecteurs de menaces natifs du cloud sont activés | C6: Les outils de détection des menaces fournis par la plateforme cloud surveillent les activités du cloud (plan de gestion, événements, etc.) afin d’identifier des comportements suspects ou des attaques potentielles. | D6: 4 | E6: =IFERROR(VLOOKUP(D6,Feuil1!A:B,2,FALSE),"") -> Maîtrisé | F6: =IFERROR(VLOOKUP(D6,Feuil1!A:C,3,FALSE),"") -> La sécurité est centralisée et largement automatisée. Elle est intégrée dans l’Infrastructure as Code et les pipelines de déploiement.
A7: LOG-05.1 | B7: Les configurations de télémétrie de sécurité cloud sont déployées automatiquement et de manière cohérente | C7: Les configurations de télémétrie de sécurité (logs, événements de sécurité, données de surveillance) sont automatiquement déployées sur les différents composants du cloud : ressources, services et workloads. | D7: 3 | E7: =IFERROR(VLOOKUP(D7,Feuil1!A:B,2,FALSE),"") -> Défini | F7: =IFERROR(VLOOKUP(D7,Feuil1!A:C,3,FALSE),"") -> Les politiques de sécurité sont centralisées et standardisées. Certaines automatisations apparaissent et des outils de sécurité cloud commencent à être utilisés.
A8: LOG-05.2 | B8: Des outils automatisés vérifient que la télémétrie de sécurité et les mécanismes de détection sont actifs et efficaces | C8: Des outils automatisés vérifient que les systèmes de télémétrie et de détection de sécurité fonctionnent correctement. | D8: 2 | E8: =IFERROR(VLOOKUP(D8,Feuil1!A:B,2,FALSE),"") -> Répétable | F8: =IFERROR(VLOOKUP(D8,Feuil1!A:C,3,FALSE),"") -> Des politiques de sécurité existent, mais elles sont appliquées manuellement et de façon incohérente selon les équipes. L’automatisation et le MFA sont encore limités.

Sheet Sécurité des charges de travail
A1: ID | B1: Nom du contrôle | C1: Description du contrôle | D1: Niveau de maturité | E1: Libellé | F1: Signification | G1: Commentaires
A2: WKL-02.1 | B2: Certaines instances/VM sont gérées avec des outils de gestion de configuration | C2: Certaines machines virtuelles ou instances cloud utilisent des outils de gestion de configuration pour automatiser leur configuration, plutôt que d’être gérées entièrement manuellement. | D2: 1 | E2: =IFERROR(VLOOKUP(D2,Feuil1!A:B,2,FALSE),"") -> Initiale | F2: =IFERROR(VLOOKUP(D2,Feuil1!A:C,3,FALSE),"") -> La sécurité est gérée manuellement et de manière non structurée. Peu d’utilisation des fonctionnalités avancées du cloud et IAM peu organisé.
A3: WKL-02.2 | B3: Les instances/VM sont analysées pour détecter les vulnérabilités | C3: Les machines virtuelles et instances cloud sont régulièrement analysées afin d’identifier les vulnérabilités de sécurité. | D3: 4 | E3: =IFERROR(VLOOKUP(D3,Feuil1!A:B,2,FALSE),"") -> Maîtrisé | F3: =IFERROR(VLOOKUP(D3,Feuil1!A:C,3,FALSE),"") -> La sécurité est centralisée et largement automatisée. Elle est intégrée dans l’Infrastructure as Code et les pipelines de déploiement.
A4: WKL-03.1 | B4: Les conteneurs utilisent la plateforme d’orchestration du fournisseur cloud | C4: Les conteneurs sont gérés via une plateforme d’orchestration fournie par le fournisseur cloud (par exemple Kubernetes managé), ce qui réduit la complexité et les risques de sécurité. | D4: 5 | E4: =IFERROR(VLOOKUP(D4,Feuil1!A:B,2,FALSE),"") -> Optimisé | F4: =IFERROR(VLOOKUP(D4,Feuil1!A:C,3,FALSE),"") -> La sécurité est entièrement intégrée, automatisée et pilotée par des plateformes centralisées. Les contrôles sont cohérents et appliqués à grande échelle.
A5: WKL-03.2 | B5: Utilisation modérée d’instances/VM immuables | C5: Certaines charges de travail utilisent des instances immuables avec autoscaling. | D5: 3 | E5: =IFERROR(VLOOKUP(D5,Feuil1!A:B,2,FALSE),"") -> Défini | F5: =IFERROR(VLOOKUP(D5,Feuil1!A:C,3,FALSE),"") -> Les politiques de sécurité sont centralisées et standardisées. Certaines automatisations apparaissent et des outils de sécurité cloud commencent à être utilisés.
A6: WKL-03.3 | B6: L’utilisation d’instances/VM de longue durée est limitée | C6: Les instances cloud ne restent pas actives pendant de longues périodes afin de réduire les risques liés aux systèmes non mis à jour ou abandonnés. | D6: 1 | E6: =IFERROR(VLOOKUP(D6,Feuil1!A:B,2,FALSE),"") -> Initiale | F6: =IFERROR(VLOOKUP(D6,Feuil1!A:C,3,FALSE),"") -> La sécurité est gérée manuellement et de manière non structurée. Peu d’utilisation des fonctionnalités avancées du cloud et IAM peu organisé.
A7: WKL-04.1 | B7: Les images sont créées via des pipelines CI/CD avec des tests de sécurité intégrés | C7: Les images utilisées pour les workloads sont créées via des pipelines CI/CD intégrant des analyses de sécurité (par exemple analyse de dépendances et analyse de vulnérabilités) afin de garantir une base sécurisée. | D7: 3 | E7: =IFERROR(VLOOKUP(D7,Feuil1!A:B,2,FALSE),"") -> Défini | F7: =IFERROR(VLOOKUP(D7,Feuil1!A:C,3,FALSE),"") -> Les politiques de sécurité sont centralisées et standardisées. Certaines automatisations apparaissent et des outils de sécurité cloud commencent à être utilisés.
A8: WKL-04.2 | B8: Une plateforme de sécurité des conteneurs est en place | C8: Une plateforme de sécurité permet de protéger les environnements de conteneurs, notamment en analysant : - les images de conteneurs - la configuration de l’orchestrateur - la sécurité au runtime. | D8: 4 | E8: =IFERROR(VLOOKUP(D8,Feuil1!A:B,2,FALSE),"") -> Maîtrisé | F8: =IFERROR(VLOOKUP(D8,Feuil1!A:C,3,FALSE),"") -> La sécurité est centralisée et largement automatisée. Elle est intégrée dans l’Infrastructure as Code et les pipelines de déploiement.
A9: WKL-04.3 | B9: Les fonctions serverless (FaaS) n’ont pas de privilèges excessifs | C9: Les fonctions serverless utilisent des permissions minimales et évitent les privilèges administratifs afin de limiter les risques de sécurité. | D9: 2 | E9: =IFERROR(VLOOKUP(D9,Feuil1!A:B,2,FALSE),"") -> Répétable | F9: =IFERROR(VLOOKUP(D9,Feuil1!A:C,3,FALSE),"") -> Des politiques de sécurité existent, mais elles sont appliquées manuellement et de façon incohérente selon les équipes. L’automatisation et le MFA sont encore limités.
A10: WKL-04.4 | B10: L’analyse de vulnérabilités cloud-native est utilisée de manière cohérente | C10: Les workloads cloud sont régulièrement analysés pour détecter les vulnérabilités à l’aide d’outils d’analyse adaptés au cloud. | D10: 2 | E10: =IFERROR(VLOOKUP(D10,Feuil1!A:B,2,FALSE),"") -> Répétable | F10: =IFERROR(VLOOKUP(D10,Feuil1!A:C,3,FALSE),"") -> Des politiques de sécurité existent, mais elles sont appliquées manuellement et de façon incohérente selon les équipes. L’automatisation et le MFA sont encore limités.
A11: WKL-05.1 | B11: Les workloads immuables sont la norme et n’exposent pas de ports d’administration | C11: Les workloads sont majoritairement immuables et utilisent l’autoscaling. Les ports d’administration à distance (ex. SSH ou RDP) sont désactivés afin de réduire la surface d’attaque. | D11: 2 | E11: =IFERROR(VLOOKUP(D11,Feuil1!A:B,2,FALSE),"") -> Répétable | F11: =IFERROR(VLOOKUP(D11,Feuil1!A:C,3,FALSE),"") -> Des politiques de sécurité existent, mais elles sont appliquées manuellement et de façon incohérente selon les équipes. L’automatisation et le MFA sont encore limités.
A12: WKL-05.2 | B12: Les workloads immuables sont la norme et n’exposent pas de ports d’administration | C12: Les workloads sont majoritairement immuables et utilisent l’autoscaling. Les ports d’administration à distance (ex. SSH ou RDP) sont désactivés afin de réduire la surface d’attaque. | D12: 2 | E12: =IFERROR(VLOOKUP(D12,Feuil1!A:B,2,FALSE),"") -> Répétable | F12: =IFERROR(VLOOKUP(D12,Feuil1!A:C,3,FALSE),"") -> Des politiques de sécurité existent, mais elles sont appliquées manuellement et de façon incohérente selon les équipes. L’automatisation et le MFA sont encore limités.

Sheet Sécurité réseau
A1: ID | B1: Nom du contrôle | C1: Description du contrôle | D1: Niveau de maturité | E1: Libellé | F1: Signification | G1: Commentaires
A2: NET-02.1 | B2: Ports sensibles non exposés | C2: Les ports sensibles (par exemple SSH, RDP ou ports de bases de données) ne sont pas accessibles directement depuis Internet. | D2: 1 | E2: =IFERROR(VLOOKUP(D2,Feuil1!A:B,2,FALSE),"") -> Initiale | F2: =IFERROR(VLOOKUP(D2,Feuil1!A:C,3,FALSE),"") -> La sécurité est gérée manuellement et de manière non structurée. Peu d’utilisation des fonctionnalités avancées du cloud et IAM peu organisé.
A3: NET-03.1 | B3: Ressources non exposées | C3: Les ressources cloud (machines virtuelles, conteneurs, etc.) sont protégées par des mécanismes de sécurité réseau comme des load balancers ou des règles de filtrage, et sont idéalement placées dans des réseaux privés. | D3: 4 | E3: =IFERROR(VLOOKUP(D3,Feuil1!A:B,2,FALSE),"") -> Maîtrisé | F3: =IFERROR(VLOOKUP(D3,Feuil1!A:C,3,FALSE),"") -> La sécurité est centralisée et largement automatisée. Elle est intégrée dans l’Infrastructure as Code et les pipelines de déploiement.
A4: NET-03.2 | B4: Ports réseau limités | C4: Les règles de sécurité réseau limitent les ports ouverts afin de réduire les surfaces d’attaque. | D4: 5 | E4: =IFERROR(VLOOKUP(D4,Feuil1!A:B,2,FALSE),"") -> Optimisé | F4: =IFERROR(VLOOKUP(D4,Feuil1!A:C,3,FALSE),"") -> La sécurité est entièrement intégrée, automatisée et pilotée par des plateformes centralisées. Les contrôles sont cohérents et appliqués à grande échelle.
A5: NET-04.1 | B5: Réseaux déployés via IaC | C5: Les configurations réseau sont déployées et maintenues à l’aide de modèles automatisés (IaC) basés sur des configurations sécurisées approuvées | D5: 2 | E5: =IFERROR(VLOOKUP(D5,Feuil1!A:B,2,FALSE),"") -> Répétable | F5: =IFERROR(VLOOKUP(D5,Feuil1!A:C,3,FALSE),"") -> Des politiques de sécurité existent, mais elles sont appliquées manuellement et de façon incohérente selon les équipes. L’automatisation et le MFA sont encore limités.
A6: NET-04.2 | B6: Mise en place d’une architecture réseau minimale sécurisée | C6: Les architectures réseau cloud utilisent uniquement les ressources nécessaires au fonctionnement des applications, avec : - des règles de sécurité strictes - des tables de routage limitées - une segmentation du réseau. Cela permet de réduire la surface d’attaque et limiter l’impact d’un incident réseau. | D6: 3 | E6: =IFERROR(VLOOKUP(D6,Feuil1!A:B,2,FALSE),"") -> Défini | F6: =IFERROR(VLOOKUP(D6,Feuil1!A:C,3,FALSE),"") -> Les politiques de sécurité sont centralisées et standardisées. Certaines automatisations apparaissent et des outils de sécurité cloud commencent à être utilisés.
A7: NET-05.1 | B7: Les mauvaises configurations réseau exposées à Internet sont corrigées automatiquement | C7: Des outils automatisés détectent et corrigent les mauvaises configurations réseau exposées à Internet, comme : - l’ouverture de ports sensibles (ex. SSH, RDP) - des règles réseau trop permissives. | D7: 2 | E7: =IFERROR(VLOOKUP(D7,Feuil1!A:B,2,FALSE),"") -> Répétable | F7: =IFERROR(VLOOKUP(D7,Feuil1!A:C,3,FALSE),"") -> Des politiques de sécurité existent, mais elles sont appliquées manuellement et de façon incohérente selon les équipes. L’automatisation et le MFA sont encore limités.

Sheet Sécurité des Données
A1: ID | B1: Nom du contrôle | C1: Description du contrôle | D1: Niveau de maturité | E1: Libellé | F1: Signification | G1: Commentaires
A2: DAT-02.1 | B2: Stockage non public | C2: Le stockage d’objets n’est pas public sans autorisation. | D2: 4 | E2: =IFERROR(VLOOKUP(D2,Feuil1!A:B,2,FALSE),"") -> Maîtrisé | F2: =IFERROR(VLOOKUP(D2,Feuil1!A:C,3,FALSE),"") -> La sécurité est centralisée et largement automatisée. Elle est intégrée dans l’Infrastructure as Code et les pipelines de déploiement.
A3: DAT-02.2 | B3: Chiffrement par défaut | C3: Les volumes de stockage utilisent le chiffrement par défaut. | D3: 3 | E3: =IFERROR(VLOOKUP(D3,Feuil1!A:B,2,FALSE),"") -> Défini | F3: =IFERROR(VLOOKUP(D3,Feuil1!A:C,3,FALSE),"") -> Les politiques de sécurité sont centralisées et standardisées. Certaines automatisations apparaissent et des outils de sécurité cloud commencent à être utilisés.
A4: DAT-03.1 | B4: Protection contre stockage public | C4: Les contrôles cloud empêchent l’exposition publique du stockage. | D4: 3 | E4: =IFERROR(VLOOKUP(D4,Feuil1!A:B,2,FALSE),"") -> Défini | F4: =IFERROR(VLOOKUP(D4,Feuil1!A:C,3,FALSE),"") -> Les politiques de sécurité sont centralisées et standardisées. Certaines automatisations apparaissent et des outils de sécurité cloud commencent à être utilisés.
A5: DAT-03.2 | B5: Clés de chiffrement gérées | C5: Certaines ressources utilisent des clés gérées par le client. | D5: 4 | E5: =IFERROR(VLOOKUP(D5,Feuil1!A:B,2,FALSE),"") -> Maîtrisé | F5: =IFERROR(VLOOKUP(D5,Feuil1!A:C,3,FALSE),"") -> La sécurité est centralisée et largement automatisée. Elle est intégrée dans l’Infrastructure as Code et les pipelines de déploiement.
A6: DAT-04.1 | B6: Détection des expositions publiques | C6: Les déploiements sont analysés pour détecter les expositions publiques. | D6: 5 | E6: =IFERROR(VLOOKUP(D6,Feuil1!A:B,2,FALSE),"") -> Optimisé | F6: =IFERROR(VLOOKUP(D6,Feuil1!A:C,3,FALSE),"") -> La sécurité est entièrement intégrée, automatisée et pilotée par des plateformes centralisées. Les contrôles sont cohérents et appliqués à grande échelle.
A7: DAT-04.2 | B7: Clés avec moindre privilège | C7: Les clés de chiffrement respectent le principe du moindre privilège. | D7: 2 | E7: =IFERROR(VLOOKUP(D7,Feuil1!A:B,2,FALSE),"") -> Répétable | F7: =IFERROR(VLOOKUP(D7,Feuil1!A:C,3,FALSE),"") -> Des politiques de sécurité existent, mais elles sont appliquées manuellement et de façon incohérente selon les équipes. L’automatisation et le MFA sont encore limités.
A8: DAT-05.1 | B8: Détection de données sensibles | C8: Les déploiements sont analysés pour détecter des données sensibles non autorisées. | D8: 2 | E8: =IFERROR(VLOOKUP(D8,Feuil1!A:B,2,FALSE),"") -> Répétable | F8: =IFERROR(VLOOKUP(D8,Feuil1!A:C,3,FALSE),"") -> Des politiques de sécurité existent, mais elles sont appliquées manuellement et de façon incohérente selon les équipes. L’automatisation et le MFA sont encore limités.
A9: DAT-05.2 | B9: Correction automatique des expositions | C9: Les expositions publiques de données sont corrigées automatiquement. | D9: 3 | E9: =IFERROR(VLOOKUP(D9,Feuil1!A:B,2,FALSE),"") -> Défini | F9: =IFERROR(VLOOKUP(D9,Feuil1!A:C,3,FALSE),"") -> Les politiques de sécurité sont centralisées et standardisées. Certaines automatisations apparaissent et des outils de sécurité cloud commencent à être utilisés.

Sheet Analyse des risques
A1: ID | B1: Nom du contrôle | C1: Description du contrôle | D1: Niveau de maturité | E1: Libellé | F1: Signification | G1: Commentaires
A2: RSK-02.1 | B2: Les fournisseurs cloud font l’objet d’une évaluation des risques | C2: Une équipe sécurité ou gestion des risques réalise une évaluation des risques avant l’autorisation d’utilisation d’un nouveau fournisseur cloud. Un registre des fournisseurs approuvés est maintenu. Le processus peut encore être partiellement informel, mais il doit être documenté. | D2: 1 | E2: =IFERROR(VLOOKUP(D2,Feuil1!A:B,2,FALSE),"") -> Initiale | F2: =IFERROR(VLOOKUP(D2,Feuil1!A:C,3,FALSE),"") -> La sécurité est gérée manuellement et de manière non structurée. Peu d’utilisation des fonctionnalités avancées du cloud et IAM peu organisé.
A3: RSK-03.1 | B3: Le registre des fournisseurs cloud indique les types de données autorisés | C3: Le registre des fournisseurs cloud précise quels types ou niveaux de classification de données peuvent être utilisés avec chaque fournisseur. Cela permet d’aligner le niveau de risque du fournisseur avec la sensibilité des données traitées. | D3: 5 | E3: =IFERROR(VLOOKUP(D3,Feuil1!A:B,2,FALSE),"") -> Optimisé | F3: =IFERROR(VLOOKUP(D3,Feuil1!A:C,3,FALSE),"") -> La sécurité est entièrement intégrée, automatisée et pilotée par des plateformes centralisées. Les contrôles sont cohérents et appliqués à grande échelle.
A4: RSK-04.1 | B4: Le registre cloud inclut les niveaux de risque et les autorisations des services | C4: Le registre des fournisseurs cloud inclut les services proposés, leur niveau de risque et les classifications de données autorisées. Par exemple, certains services peuvent être autorisés uniquement pour des données non sensibles. | D4: 4 | E4: =IFERROR(VLOOKUP(D4,Feuil1!A:B,2,FALSE),"") -> Maîtrisé | F4: =IFERROR(VLOOKUP(D4,Feuil1!A:C,3,FALSE),"") -> La sécurité est centralisée et largement automatisée. Elle est intégrée dans l’Infrastructure as Code et les pipelines de déploiement.
A5: RSK-04.2 | B5: La sécurité réalise des analyses de risques sur les déploiements cloud en production | C5: L’équipe sécurité réalise des évaluations de risques documentées pour les déploiements cloud en production. Ces évaluations sont réalisées régulièrement (par exemple chaque année) ou lors de changements majeurs dans l’architecture ou l’application. | D5: 3 | E5: =IFERROR(VLOOKUP(D5,Feuil1!A:B,2,FALSE),"") -> Défini | F5: =IFERROR(VLOOKUP(D5,Feuil1!A:C,3,FALSE),"") -> Les politiques de sécurité sont centralisées et standardisées. Certaines automatisations apparaissent et des outils de sécurité cloud commencent à être utilisés.
A6: RSK-05.1 | B6: Un processus formel est utilisé pour évaluer les risques des déploiements cloud | C6: L’organisation utilise un processus formel et des critères définis pour évaluer les risques des déploiements cloud avant leur mise en production. Les analyses de risques sont mises à jour régulièrement et des plans de remédiation sont définis pour les risques identifiés. | D6: 2 | E6: =IFERROR(VLOOKUP(D6,Feuil1!A:B,2,FALSE),"") -> Répétable | F6: =IFERROR(VLOOKUP(D6,Feuil1!A:C,3,FALSE),"") -> Des politiques de sécurité existent, mais elles sont appliquées manuellement et de façon incohérente selon les équipes. L’automatisation et le MFA sont encore limités.
A7: RSK-05.2 | B7: Les risques des fournisseurs cloud sont évalués en continu | C7: Les risques associés aux fournisseurs cloud et à leurs services sont évalués régulièrement afin de prendre en compte les nouvelles fonctionnalités ou les changements de services. Les services peuvent être autorisés ou restreints selon le type de données qu’ils traitent. | D7: 3 | E7: =IFERROR(VLOOKUP(D7,Feuil1!A:B,2,FALSE),"") -> Défini | F7: =IFERROR(VLOOKUP(D7,Feuil1!A:C,3,FALSE),"") -> Les politiques de sécurité sont centralisées et standardisées. Certaines automatisations apparaissent et des outils de sécurité cloud commencent à être utilisés.

Sheet Résilience
A1: ID | B1: Nom du contrôle | C1: Description du contrôle | D1: Niveau de maturité | E1: Libellé | F1: Signification | G1: Commentaires
A2: BCR-02.1 | B2: Autoscaling multi-zones de disponibilité utilisé | C2: Les ressources de calcul sont déployées dans plusieurs zones de disponibilité grâce à l’autoscaling. Cela permet d’améliorer la résilience du système en cas de panne d’une zone ou d’une ressource. | D2: 3 | E2: =IFERROR(VLOOKUP(D2,Feuil1!A:B,2,FALSE),"") -> Défini | F2: =IFERROR(VLOOKUP(D2,Feuil1!A:C,3,FALSE),"") -> Les politiques de sécurité sont centralisées et standardisées. Certaines automatisations apparaissent et des outils de sécurité cloud commencent à être utilisés.
A3: BCR-03.1 | B3: Les machines virtuelles et bases de données disposent de snapshots récents | C3: Des snapshots ou sauvegardes réguliers sont réalisés pour les machines virtuelles et les bases de données. Cela permet de restaurer rapidement les systèmes et de limiter les pertes de données en cas d’incident. | D3: 1 | E3: =IFERROR(VLOOKUP(D3,Feuil1!A:B,2,FALSE),"") -> Initiale | F3: =IFERROR(VLOOKUP(D3,Feuil1!A:C,3,FALSE),"") -> La sécurité est gérée manuellement et de manière non structurée. Peu d’utilisation des fonctionnalités avancées du cloud et IAM peu organisé.
A4: BCR-03.2 | B4: Cycle de vie ou sauvegardes du stockage d’objets configurés | C4: Les données stockées dans les services de stockage d’objets utilisent des politiques de cycle de vie ou des sauvegardes automatiques. Cela permet d’assurer la conservation et la récupération des données importantes en cas d’incident. | D4: 5 | E4: =IFERROR(VLOOKUP(D4,Feuil1!A:B,2,FALSE),"") -> Optimisé | F4: =IFERROR(VLOOKUP(D4,Feuil1!A:C,3,FALSE),"") -> La sécurité est entièrement intégrée, automatisée et pilotée par des plateformes centralisées. Les contrôles sont cohérents et appliqués à grande échelle.
A5: BCR-04.1 | B5: Most compute workloads are autoscaled or serverless | C5: Most compute workloads, including instances/VMs/containers, are autoscaled. Autoscaling is a cloud-native architectural pattern that increases resiliency of running workloads. Autoscaling can be implemented in VMs/instances or containers. Serverless functions, by their nature, are ephemeral and autoscaled. To reach maturity Level 4, most workloads (>60%) in production environments are autoscaled. | D5: 4 | E5: =IFERROR(VLOOKUP(D5,Feuil1!A:B,2,FALSE),"") -> Maîtrisé | F5: =IFERROR(VLOOKUP(D5,Feuil1!A:C,3,FALSE),"") -> La sécurité est centralisée et largement automatisée. Elle est intégrée dans l’Infrastructure as Code et les pipelines de déploiement.
A6: BCR-04.2 | B6: La majorité des charges de calcul utilisent l’autoscaling ou le serverless | C6: La plupart des charges de travail utilisent des mécanismes d’autoscaling ou des architectures serverless. Ces approches cloud-native améliorent la résilience et l’adaptation automatique aux variations de charge. | D6: 2 | E6: =IFERROR(VLOOKUP(D6,Feuil1!A:B,2,FALSE),"") -> Répétable | F6: =IFERROR(VLOOKUP(D6,Feuil1!A:C,3,FALSE),"") -> Des politiques de sécurité existent, mais elles sont appliquées manuellement et de façon incohérente selon les équipes. L’automatisation et le MFA sont encore limités.
A7: BCR-04.3 | B7: Les données critiques sont accessibles dans au moins deux régions | C7: Les données critiques, notamment dans les bases de données ou le stockage d’objets, sont répliquées dans plusieurs régions cloud. Cela permet d’assurer la continuité d’activité en cas d’indisponibilité d’une région. | D7: 2 | E7: =IFERROR(VLOOKUP(D7,Feuil1!A:B,2,FALSE),"") -> Répétable | F7: =IFERROR(VLOOKUP(D7,Feuil1!A:C,3,FALSE),"") -> Des politiques de sécurité existent, mais elles sont appliquées manuellement et de façon incohérente selon les équipes. L’automatisation et le MFA sont encore limités.
A8: BCR-05.1 | B8: Tous les déploiements en production utilisent l’infrastructure as code | C8: Les infrastructures de production sont entièrement déployées et gérées à l’aide d’outils d’infrastructure as code. Cela garantit des déploiements cohérents, reproductibles et facilite la reconstruction rapide des environnements. | D8: 3 | E8: =IFERROR(VLOOKUP(D8,Feuil1!A:B,2,FALSE),"") -> Défini | F8: =IFERROR(VLOOKUP(D8,Feuil1!A:C,3,FALSE),"") -> Les politiques de sécurité sont centralisées et standardisées. Certaines automatisations apparaissent et des outils de sécurité cloud commencent à être utilisés.
A9: BCR-05.2 | B9: Le chaos engineering est mis en œuvre | C9: Des tests de résilience sont réalisés en introduisant volontairement des pannes contrôlées dans le système. Cette approche permet de vérifier la capacité des systèmes à se rétablir automatiquement et à maintenir la continuité des services. | D9: 4 | E9: =IFERROR(VLOOKUP(D9,Feuil1!A:B,2,FALSE),"") -> Maîtrisé | F9: =IFERROR(VLOOKUP(D9,Feuil1!A:C,3,FALSE),"") -> La sécurité est centralisée et largement automatisée. Elle est intégrée dans l’Infrastructure as Code et les pipelines de déploiement.

Sheet Conformité
A1: ID | B1: Nom du contrôle | C1: Description du contrôle | D1: Niveau de maturité | E1: Libellé | F1: Signification | G1: Commentaires
A2: CA-02.1 | B2: La conformité de base est évaluée manuellement | C2: Les déploiements cloud sont évalués pour vérifier leur conformité aux exigences réglementaires ou internes. L’évaluation repose principalement sur des vérifications manuelles, par exemple à l’aide de checklists, éventuellement complétées par certains outils de sécurité. | D2: 5 | E2: =IFERROR(VLOOKUP(D2,Feuil1!A:B,2,FALSE),"") -> Optimisé | F2: =IFERROR(VLOOKUP(D2,Feuil1!A:C,3,FALSE),"") -> La sécurité est entièrement intégrée, automatisée et pilotée par des plateformes centralisées. Les contrôles sont cohérents et appliqués à grande échelle.
A3: CA-03.1 | B3: Les fournisseurs et services cloud autorisés pour les données réglementées sont définis | C3: L’organisation maintient une liste des fournisseurs et services cloud autorisés pour traiter certains types de données réglementées. Cette liste précise les exigences de conformité applicables et les conditions d’utilisation associées. | D3: 2 | E3: =IFERROR(VLOOKUP(D3,Feuil1!A:B,2,FALSE),"") -> Répétable | F3: =IFERROR(VLOOKUP(D3,Feuil1!A:C,3,FALSE),"") -> Des politiques de sécurité existent, mais elles sont appliquées manuellement et de façon incohérente selon les équipes. L’automatisation et le MFA sont encore limités.
A4: CA-03.2 | B4: Les déploiements sont évalués pour la conformité avant mise en production | C4: Les déploiements concernés par des exigences de conformité sont évalués avant leur mise en production et de manière périodique par la suite. Ces évaluations peuvent utiliser des outils automatisés, mais l’approbation finale reste généralement manuelle. | D4: 3 | E4: =IFERROR(VLOOKUP(D4,Feuil1!A:B,2,FALSE),"") -> Défini | F4: =IFERROR(VLOOKUP(D4,Feuil1!A:C,3,FALSE),"") -> Les politiques de sécurité sont centralisées et standardisées. Certaines automatisations apparaissent et des outils de sécurité cloud commencent à être utilisés.
A5: CA-04.1 | B5: La conformité technique est évaluée en continu avec des outils automatisés | C5: Les configurations cloud sont analysées automatiquement afin de vérifier leur conformité avec les standards et réglementations applicables. Ces contrôles sont généralement réalisés à l’aide d’outils de sécurité ou de conformité cloud. | D5: 1 | E5: =IFERROR(VLOOKUP(D5,Feuil1!A:B,2,FALSE),"") -> Initiale | F5: =IFERROR(VLOOKUP(D5,Feuil1!A:C,3,FALSE),"") -> La sécurité est gérée manuellement et de manière non structurée. Peu d’utilisation des fonctionnalités avancées du cloud et IAM peu organisé.
A6: CA-04.2 | B6: Des garde-fous préventifs sont mis en place pour la conformité | C6: Des règles préventives empêchent la mise en place de configurations non conformes dans les environnements cloud. Par exemple, certaines politiques peuvent bloquer l’utilisation de services ou de régions non autorisés. | D6: 4 | E6: =IFERROR(VLOOKUP(D6,Feuil1!A:B,2,FALSE),"") -> Maîtrisé | F6: =IFERROR(VLOOKUP(D6,Feuil1!A:C,3,FALSE),"") -> La sécurité est centralisée et largement automatisée. Elle est intégrée dans l’Infrastructure as Code et les pipelines de déploiement.
A7: CA-05.1 | B7: Le reporting de conformité est automatisé et centralisé | C7: Des tableaux de bord centralisés permettent de suivre l’état de conformité des environnements cloud. Les rapports et les preuves de conformité sont générés automatiquement et consolidés à l’échelle de l’organisation. | D7: 1 | E7: =IFERROR(VLOOKUP(D7,Feuil1!A:B,2,FALSE),"") -> Initiale | F7: =IFERROR(VLOOKUP(D7,Feuil1!A:C,3,FALSE),"") -> La sécurité est gérée manuellement et de manière non structurée. Peu d’utilisation des fonctionnalités avancées du cloud et IAM peu organisé.

Sheet Gestion des incidents 
A1: ID | B1: Nom du contrôle | C1: Description du contrôle | D1: Niveau de maturité | E1: Libellé | F1: Signfication | G1: Commentaires
A2: IR-02.1 | B2: Une équipe de réponse aux incidents cloud est désignée | C2: Une équipe ou un service est chargé de répondre aux incidents de sécurité dans les environnements cloud. Les procédures de réponse aux incidents sont documentées et adaptées aux spécificités du cloud, même si elles restent principalement manuelles. | D2: 1 | E2: =IFERROR(VLOOKUP(D2,Feuil1!A:B,2,FALSE),"") -> Initiale | F2: =IFERROR(VLOOKUP(D2,Feuil1!A:C,3,FALSE),"") -> La sécurité est gérée manuellement et de manière non structurée. Peu d’utilisation des fonctionnalités avancées du cloud et IAM peu organisé.
A3: IR-03.1 | B3: Des playbooks de réponse aux incidents cloud sont documentés | C3: Des playbooks documentent les procédures de réponse pour les principaux types d’incidents cloud. Ces playbooks peuvent couvrir des situations comme l’exposition de données, la compromission d’identifiants ou l’accès non autorisé à des ressources cloud. | D3: 4 | E3: =IFERROR(VLOOKUP(D3,Feuil1!A:B,2,FALSE),"") -> Maîtrisé | F3: =IFERROR(VLOOKUP(D3,Feuil1!A:C,3,FALSE),"") -> La sécurité est centralisée et largement automatisée. Elle est intégrée dans l’Infrastructure as Code et les pipelines de déploiement.
A4: IR-03.2 | B4: Les équipes de réponse aux incidents ont un accès en lecture aux déploiements cloud | C4: Les équipes de réponse aux incidents disposent au minimum d’un accès en lecture aux ressources et configurations des environnements cloud. Cela leur permet d’analyser les incidents en utilisant les journaux, la configuration des ressources et le contexte technique des déploiements. | D4: 3 | E4: =IFERROR(VLOOKUP(D4,Feuil1!A:B,2,FALSE),"") -> Défini | F4: =IFERROR(VLOOKUP(D4,Feuil1!A:C,3,FALSE),"") -> Les politiques de sécurité sont centralisées et standardisées. Certaines automatisations apparaissent et des outils de sécurité cloud commencent à être utilisés.
A5: IR-04.1 | B5: Automatisation de la détection et de la réponse aux incidents cloud | C5: Des outils permettent d’automatiser la détection, l’enrichissement et la priorisation des incidents de sécurité dans le cloud. Ces solutions peuvent inclure des plateformes CDR, SOAR ou d’autres outils d’automatisation pour accélérer l’analyse et la réponse aux incidents. | D5: 4 | E5: =IFERROR(VLOOKUP(D5,Feuil1!A:B,2,FALSE),"") -> Maîtrisé | F5: =IFERROR(VLOOKUP(D5,Feuil1!A:C,3,FALSE),"") -> La sécurité est centralisée et largement automatisée. Elle est intégrée dans l’Infrastructure as Code et les pipelines de déploiement.
A6: IR-04.2 | B6: Outils d’automatisation pour la réponse aux incidents | C6: Des outils ou scripts automatisés assistent les équipes dans les tâches de réponse aux incidents. Ils peuvent par exemple collecter des informations, créer des snapshots, isoler des ressources compromises ou révoquer des identifiants. | D6: 5 | E6: =IFERROR(VLOOKUP(D6,Feuil1!A:B,2,FALSE),"") -> Optimisé | F6: =IFERROR(VLOOKUP(D6,Feuil1!A:C,3,FALSE),"") -> La sécurité est entièrement intégrée, automatisée et pilotée par des plateformes centralisées. Les contrôles sont cohérents et appliqués à grande échelle.
A7: IR-04.3 | B7: Les équipes peuvent escalader vers un accès administrateur complet | C7: En cas d’incident majeur, les équipes de réponse aux incidents peuvent obtenir temporairement un accès administrateur complet aux environnements cloud. Ce type d’accès doit être contrôlé par un mécanisme sécurisé, avec authentification forte et traçabilité | D7: 2 | E7: =IFERROR(VLOOKUP(D7,Feuil1!A:B,2,FALSE),"") -> Répétable | F7: =IFERROR(VLOOKUP(D7,Feuil1!A:C,3,FALSE),"") -> Des politiques de sécurité existent, mais elles sont appliquées manuellement et de façon incohérente selon les équipes. L’automatisation et le MFA sont encore limités.
A8: IR-05.1 | B8: Remédiation automatique des incidents | C8: Certaines actions de remédiation sont automatisées afin de corriger rapidement des incidents connus. Par exemple, une mauvaise configuration de sécurité peut être détectée et corrigée automatiquement pour limiter les risques. | D8: 2 | E8: =IFERROR(VLOOKUP(D8,Feuil1!A:B,2,FALSE),"") -> Répétable | F8: =IFERROR(VLOOKUP(D8,Feuil1!A:C,3,FALSE),"") -> Des politiques de sécurité existent, mais elles sont appliquées manuellement et de façon incohérente selon les équipes. L’automatisation et le MFA sont encore limités.
A9: IR-05.2 | B9: Les équipes cloud et développement participent à la réponse aux incidents | C9: Les équipes de développement et d’exploitation participent activement à la gestion des incidents affectant leurs environnements cloud. Des outils collaboratifs ou des workflows automatisés facilitent la communication et l’escalade des incidents. | D9: 1 | E9: =IFERROR(VLOOKUP(D9,Feuil1!A:B,2,FALSE),"") -> Initiale | F9: =IFERROR(VLOOKUP(D9,Feuil1!A:C,3,FALSE),"") -> La sécurité est gérée manuellement et de manière non structurée. Peu d’utilisation des fonctionnalités avancées du cloud et IAM peu organisé.

Sheet Sécurité Applicative
A1: ID | B1: Nom du contrôle | C1: Description du contrôle | D1: Niveau de maturité | E1: Libellé | F1: Signification | G1: Commentaires
